package twilightforest.world.components.feature;

import com.mojang.serialization.Codec;
import net.minecraft.world.level.block.Block;
import net.minecraft.world.level.block.state.BlockState;
import net.minecraft.world.level.block.Blocks;
import net.minecraft.core.Direction;
import net.minecraft.core.BlockPos;
import net.minecraft.world.level.WorldGenLevel;
import net.minecraft.world.level.LevelAccessor;
import net.minecraft.world.level.levelgen.feature.Feature;
import net.minecraft.world.level.levelgen.feature.FeaturePlaceContext;
import net.minecraft.world.level.levelgen.feature.configurations.NoneFeatureConfiguration;
import twilightforest.loot.TFTreasure;
import twilightforest.util.FeatureUtil;

import java.util.Random;

public class TFGenWell extends Feature<NoneFeatureConfiguration> {

	public TFGenWell(Codec<NoneFeatureConfiguration> configIn) {
		super(configIn);
	}

	@Override
	public boolean place(FeaturePlaceContext<NoneFeatureConfiguration> ctx) {
		WorldGenLevel world = ctx.level();
		BlockPos pos = ctx.origin();
		Random rand = ctx.random();

		if (rand.nextInt(4) == 0) {
			return generate4x4Well(world, rand, pos);
		} else {
			return generate3x3Well(world, rand, pos);
		}
	}

	/**
	 * make a cute little well
	 */
	public boolean generate3x3Well(WorldGenLevel world, Random rand, BlockPos pos) {
		//if (!FeatureUtil.isAreaSuitable(world, pos, 3, 4, 3)) {
		//	return false;
		//}

		// make a cute well!
		world.setBlock(pos, Blocks.MOSSY_COBBLESTONE.defaultBlockState(), 3);
		world.setBlock(pos.offset(1, 0, 0), Blocks.MOSSY_COBBLESTONE.defaultBlockState(), 3);
		world.setBlock(pos.offset(2, 0, 0), Blocks.MOSSY_COBBLESTONE.defaultBlockState(), 3);
		world.setBlock(pos.offset(0, 0, 2), Blocks.MOSSY_COBBLESTONE.defaultBlockState(), 3);
		world.setBlock(pos.offset(1, 0, 2), Blocks.MOSSY_COBBLESTONE.defaultBlockState(), 3);
		world.setBlock(pos.offset(2, 0, 2), Blocks.MOSSY_COBBLESTONE.defaultBlockState(), 3);
		world.setBlock(pos.offset(0, 0, 1), Blocks.MOSSY_COBBLESTONE.defaultBlockState(), 3);
		world.setBlock(pos.offset(2, 0, 1), Blocks.MOSSY_COBBLESTONE.defaultBlockState(), 3);

		world.setBlock(pos.offset(1, 0, 1), Blocks.WATER.defaultBlockState(), 3);

		world.setBlock(pos.offset(0, 1, 0), Blocks.OAK_FENCE.defaultBlockState(), 3);
		world.setBlock(pos.offset(2, 1, 0), Blocks.OAK_FENCE.defaultBlockState(), 3);
		world.setBlock(pos.offset(0, 1, 2), Blocks.OAK_FENCE.defaultBlockState(), 3);
		world.setBlock(pos.offset(2, 1, 2), Blocks.OAK_FENCE.defaultBlockState(), 3);

		world.setBlock(pos.offset(0, 2, 0), Blocks.OAK_FENCE.defaultBlockState(), 3);
		world.setBlock(pos.offset(2, 2, 0), Blocks.OAK_FENCE.defaultBlockState(), 3);
		world.setBlock(pos.offset(0, 2, 2), Blocks.OAK_FENCE.defaultBlockState(), 3);
		world.setBlock(pos.offset(2, 2, 2), Blocks.OAK_FENCE.defaultBlockState(), 3);

		world.setBlock(pos.offset(0, 3, 0), Blocks.OAK_SLAB.defaultBlockState(), 3);
		world.setBlock(pos.offset(1, 3, 0), Blocks.OAK_SLAB.defaultBlockState(), 3);
		world.setBlock(pos.offset(2, 3, 0), Blocks.OAK_SLAB.defaultBlockState(), 3);
		world.setBlock(pos.offset(0, 3, 2), Blocks.OAK_SLAB.defaultBlockState(), 3);
		world.setBlock(pos.offset(1, 3, 2), Blocks.OAK_SLAB.defaultBlockState(), 3);
		world.setBlock(pos.offset(2, 3, 2), Blocks.OAK_SLAB.defaultBlockState(), 3);
		world.setBlock(pos.offset(0, 3, 1), Blocks.OAK_SLAB.defaultBlockState(), 3);
		world.setBlock(pos.offset(2, 3, 1), Blocks.OAK_SLAB.defaultBlockState(), 3);

		world.setBlock(pos.offset(1, 3, 1), Blocks.OAK_PLANKS.defaultBlockState(), 3);


		boolean madeTreasure = false;
		// now drill each the well square down 20 squares, or until we hit something
		for (int dy = -1; dy >= -20; dy--) {
			Block dblock = world.getBlockState(pos.offset(1, dy, 1)).getBlock();
			// we only drill through dirt, grass, gravel and stone
			if (dblock != Blocks.DIRT && dblock != Blocks.GRASS_BLOCK && dblock != Blocks.GRAVEL && dblock != Blocks.STONE) {
				break;
			}
			// we also need a solid block under where we're digging
			if (!world.getBlockState(pos.offset(1, dy - 1, 1)).getMaterial().isSolid()) {
				break;
			}

			// okay, we're good to dig.
			world.setBlock(pos.offset(1, dy, 1), Blocks.WATER.defaultBlockState(),3);

			// if we're below 15 squares, there's a small chance of treasure
			if (dy < -15 && !madeTreasure && rand.nextInt(8) == 0) {
				//TODO: more directions
				world.setBlock(pos.offset(2, dy, 1), Blocks.WATER.defaultBlockState(),3);
				world.setBlock(pos.offset(3, dy + 1, 1), Blocks.AIR.defaultBlockState(),3);
				world.setBlock(pos.offset(3, dy, 1), Blocks.AIR.defaultBlockState(),3);

				//TODO: unique treasure table that is themed for underwater well exploration
				TFTreasure.basement.generateChest(world, pos.offset(3, dy, 1), Direction.NORTH, false);

				// set flag so we only get one chest
				madeTreasure = true;
			}
		}

		return true;
	}

	private boolean generate4x4Well(LevelAccessor world, Random rand, BlockPos pos) {
		//if (!FeatureUtil.isAreaSuitable(world, pos, 4, 4, 4)) {
		//	return false;
		//}

		// make a cute well!
		world.setBlock(pos, Blocks.MOSSY_COBBLESTONE.defaultBlockState(), 3);
		world.setBlock(pos.offset(1, 0, 0), Blocks.MOSSY_COBBLESTONE.defaultBlockState(), 3);
		world.setBlock(pos.offset(2, 0, 0), Blocks.MOSSY_COBBLESTONE.defaultBlockState(), 3);
		world.setBlock(pos.offset(3, 0, 0), Blocks.MOSSY_COBBLESTONE.defaultBlockState(), 3);
		world.setBlock(pos.offset(0, 0, 3), Blocks.MOSSY_COBBLESTONE.defaultBlockState(), 3);
		world.setBlock(pos.offset(1, 0, 3), Blocks.MOSSY_COBBLESTONE.defaultBlockState(), 3);
		world.setBlock(pos.offset(2, 0, 3), Blocks.MOSSY_COBBLESTONE.defaultBlockState(), 3);
		world.setBlock(pos.offset(3, 0, 3), Blocks.MOSSY_COBBLESTONE.defaultBlockState(), 3);
		world.setBlock(pos.offset(0, 0, 1), Blocks.MOSSY_COBBLESTONE.defaultBlockState(), 3);
		world.setBlock(pos.offset(0, 0, 2), Blocks.MOSSY_COBBLESTONE.defaultBlockState(), 3);
		world.setBlock(pos.offset(3, 0, 1), Blocks.MOSSY_COBBLESTONE.defaultBlockState(), 3);
		world.setBlock(pos.offset(3, 0, 2), Blocks.MOSSY_COBBLESTONE.defaultBlockState(), 3);

		world.setBlock(pos.offset(1, 0, 1), Blocks.WATER.defaultBlockState(), 3);
		world.setBlock(pos.offset(2, 0, 1), Blocks.WATER.defaultBlockState(), 3);
		world.setBlock(pos.offset(1, 0, 2), Blocks.WATER.defaultBlockState(), 3);
		world.setBlock(pos.offset(2, 0, 2), Blocks.WATER.defaultBlockState(), 3);

		world.setBlock(pos.offset(0, 1, 0), Blocks.OAK_FENCE.defaultBlockState(), 3);
		world.setBlock(pos.offset(3, 1, 0), Blocks.OAK_FENCE.defaultBlockState(), 3);
		world.setBlock(pos.offset(0, 1, 3), Blocks.OAK_FENCE.defaultBlockState(), 3);
		world.setBlock(pos.offset(3, 1, 3), Blocks.OAK_FENCE.defaultBlockState(), 3);

		world.setBlock(pos.offset(0, 2, 0), Blocks.OAK_FENCE.defaultBlockState(), 3);
		world.setBlock(pos.offset(3, 2, 0), Blocks.OAK_FENCE.defaultBlockState(), 3);
		world.setBlock(pos.offset(0, 2, 3), Blocks.OAK_FENCE.defaultBlockState(), 3);
		world.setBlock(pos.offset(3, 2, 3), Blocks.OAK_FENCE.defaultBlockState(), 3);

		world.setBlock(pos.offset(0, 3, 0), Blocks.OAK_SLAB.defaultBlockState(), 3);
		world.setBlock(pos.offset(1, 3, 0), Blocks.OAK_SLAB.defaultBlockState(), 3);
		world.setBlock(pos.offset(2, 3, 0), Blocks.OAK_SLAB.defaultBlockState(), 3);
		world.setBlock(pos.offset(3, 3, 0), Blocks.OAK_SLAB.defaultBlockState(), 3);
		world.setBlock(pos.offset(0, 3, 3), Blocks.OAK_SLAB.defaultBlockState(), 3);
		world.setBlock(pos.offset(1, 3, 3), Blocks.OAK_SLAB.defaultBlockState(), 3);
		world.setBlock(pos.offset(2, 3, 3), Blocks.OAK_SLAB.defaultBlockState(), 3);
		world.setBlock(pos.offset(3, 3, 3), Blocks.OAK_SLAB.defaultBlockState(), 3);
		world.setBlock(pos.offset(0, 3, 1), Blocks.OAK_SLAB.defaultBlockState(), 3);
		world.setBlock(pos.offset(0, 3, 2), Blocks.OAK_SLAB.defaultBlockState(), 3);
		world.setBlock(pos.offset(3, 3, 1), Blocks.OAK_SLAB.defaultBlockState(), 3);
		world.setBlock(pos.offset(3, 3, 2), Blocks.OAK_SLAB.defaultBlockState(), 3);

		world.setBlock(pos.offset(1, 3, 1), Blocks.OAK_PLANKS.defaultBlockState(), 3);
		world.setBlock(pos.offset(2, 3, 1), Blocks.OAK_PLANKS.defaultBlockState(), 3);
		world.setBlock(pos.offset(1, 3, 2), Blocks.OAK_PLANKS.defaultBlockState(), 3);
		world.setBlock(pos.offset(2, 3, 2), Blocks.OAK_PLANKS.defaultBlockState(), 3);


		// now drill each of the 4 well squares down 20 squares, or until we hit something
		for (int dx = 1; dx <= 2; dx++) {
			for (int dz = 1; dz <= 2; dz++) {
				for (int dy = -1; dy >= -20; dy--) {
					BlockPos dPos = pos.offset(dx, dy, dz);
					BlockState dState = world.getBlockState(dPos);
					Block dblock = dState.getBlock();

					// we only drill through dirt, grass, gravel and stone
					if (dblock != Blocks.DIRT && dblock != Blocks.GRASS_BLOCK && dblock != Blocks.GRAVEL && dblock != Blocks.STONE) {
						break;
					}
					// we also need a solid block under where we're digging
					if (!world.getBlockState(dPos.below()).getMaterial().isSolid()) {
						break;
					}

					// okay, we're good to dig.
					world.setBlock(dPos, Blocks.WATER.defaultBlockState(), 3);
				}

			}

		}

		return true;
	}
}
